Traceback (most recent call last):
  File "/Library/Frameworks/Python.framework/Versions/3.11/lib/python3.11/site-packages/serial/serialposix.py", line 322, in open
    self.fd = os.open(self.portstr, os.O_RDWR | os.O_NOCTTY | os.O_NONBLOCK)
              ^^^^^^^^^^^^^^^^^^^^^^^^^^^^^^^^^^^^^^^^^^^^^^^^^^^^^^^^^^^^^^
OSError: [Errno 16] Resource busy: '/dev/tty.usbmodem144403'

During handling of the above exception, another exception occurred:

Traceback (most recent call last):
  File "/Users/kevinimlay/Developer/Graduate Research/STM32 RTC Scheduler/Code/Desktop Application/SerialScript.py", line 54, in <module>
    Stm32Session = SerialSession.STM32SerialCom(availablePort)
                   ^^^^^^^^^^^^^^^^^^^^^^^^^^^^^^^^^^^^^^^^^^^
  File "/Users/kevinimlay/Developer/Graduate Research/STM32 RTC Scheduler/Code/Desktop Application/SerialSession.py", line 23, in __new__
    tempStm32McuConnection = SerialProtocol.SerialProtocol(port)
                             ^^^^^^^^^^^^^^^^^^^^^^^^^^^^^^^^^^^
  File "/Users/kevinimlay/Developer/Graduate Research/STM32 RTC Scheduler/Code/Desktop Application/SerialProtocol.py", line 82, in __new__
    tempConnection.openPort(port)
  File "/Users/kevinimlay/Developer/Graduate Research/STM32 RTC Scheduler/Code/Desktop Application/SerialConnection.py", line 65, in openPort
    self._connection.open()
  File "/Library/Frameworks/Python.framework/Versions/3.11/lib/python3.11/site-packages/serial/serialposix.py", line 325, in open
    raise SerialException(msg.errno, "could not open port {}: {}".format(self._port, msg))
serial.serialutil.SerialException: [Errno 16] could not open port /dev/tty.usbmodem144403: [Errno 16] Resource busy: '/dev/tty.usbmodem144403'
